<?xml version="1.0"?>
<robot xmlns:xacro="http://www.ros.org/wiki/xacro" name="barista_robot">

    <xacro:include filename="$(find barista_robot_description)/xacro/drive_wheel.xacro" />

    <!-- Colors -->
    <material name="blue">
        <color rgba="0.006 0.151 0.781 1"/>
    </material>

    <material name="white">
        <color rgba="1.0 1.0 1.0 1"/>
    </material>

    <material name="black">
        <color rgba="0 0 0 1"/>
    </material>

    <material name="green_dark">
        <color rgba="0.0 0.5 0.0 1"/>
    </material>

    <!-- Base Link -->
    <link name="base_link">
        <visual>
            <geometry>
                <cylinder radius="0.178" length="0.155" />
            </geometry>
            <material name="blue" />
        </visual>

        <collision>
            <geometry>
                <cylinder radius="0.178" length="0.155" />
            </geometry>
        </collision>

        <inertial>
            <mass value="0.5" />
            <origin rpy="0 0 0" xyz="0 0 0" />
            <inertia ixx="0.0049615416667" ixy="0" ixz="0" iyy="0.0049615416667" iyz="0" izz="0.007921" />
        </inertial>
    </link>

    <!-- Gazebo Color for Base link-->
    <gazebo reference="base_link">
        <material>Gazebo/Blue</material>
    </gazebo>

    <!-- Drive Wheels -->
    <xacro:drive_wheel drive_wheel_name="left_drive_wheel" />
    <xacro:drive_wheel drive_wheel_name="right_drive_wheel" />

    <!-- Gazebo - Left Drive Wheel -->
    <gazebo reference="left_drive_wheel">
        <material>Gazebo/Black</material>
        <kp>1000000.0</kp>
        <kd>100.0</kd>
        <mu1>1.0</mu1>
        <mu2>1.0</mu2>
    </gazebo>

    <!-- Gazebo - Right Drive Wheel -->
    <gazebo reference="right_drive_wheel">
        <material>Gazebo/Black</material>
        <kp>1000000.0</kp>
        <kd>100.0</kd>
        <mu1>1.0</mu1>
        <mu2>1.0</mu2>
    </gazebo>

    <joint name="base_link_to_left_drive_wheel_joint" type="continuous">
        <origin rpy="0 0 0" xyz="0 0.126 -0.0775" />
        <parent link="base_link" />
        <child link="left_drive_wheel" />
        <axis xyz="0 1 0" />
    </joint>

    <joint name="base_link_to_right_drive_wheel_joint" type="continuous">
        <origin rpy="0 0 0" xyz="0 -0.126 -0.0775" />
        <parent link="base_link" />
        <child link="right_drive_wheel" />
        <axis xyz="0 1 0" />
    </joint>

    <!-- Joint State Publisher Plugin -->
    <gazebo>
        <plugin name="barista_robot_joint_state" filename="libgazebo_ros_joint_state_publisher.so">
            <ros>
                <remapping>~/out:=joint_states</remapping>
            </ros>
            <update_rate>30</update_rate>

            <joint_name>base_link_to_left_drive_wheel_joint</joint_name>
            <joint_name>base_link_to_right_drive_wheel_joint</joint_name>
        </plugin>
    </gazebo>

</robot>
